<?xml version="1.0" ?>
<robot name="urdf" xmlns:xacro="http://www.ros.org/wiki/xacro">

<xacro:include filename="$(find urdf_description)/urdf/materials.xacro" />
<xacro:include filename="$(find urdf_description)/urdf/urdf.trans" />
<!--xacro:include filename="$(find urdf_description)/urdf/urdf.gazebo" /!-->

<link name="base_footprint">
  <origin xyz="0 0 0" rpy="0 0 0"/>
  </link>
  
<link name="base_link">
  <inertial>
    <origin xyz="0.02041066771897629 -0.007575037833829778 0.06830931514078505" rpy="0 0 0"/>
    <mass value="3.4980631377264046"/>ss
    <inertia ixx="0.008369" iyy="0.005992" izz="0.01248" ixy="-0.000384" iyz="0.000156" ixz="-4.7e-05"/>
  </inertial>
  <visual>
    <origin xyz="0 0 0" rpy="0 0 0"/>
    <geometry>
      <mesh filename="package://urdf_description/meshes/base_link.stl" scale="0.001 0.001 0.001"/>
    </geometry>
    <material name="silver"/>
  </visual>
  <collision>
    <origin xyz="0 0 0" rpy="0 0 0"/>
    <geometry>
      <mesh filename="package://urdf_description/meshes/base_link.stl" scale="0.001 0.001 0.001"/>
    </geometry>
  </collision>
</link>

<link name="wheel_link_1">
  <inertial>
    <origin xyz="0.007650926996154439 -6.583497840632717e-05 7.082305684349283e-05" rpy="0 0 0"/>
    <mass value="0.17051038938064"/>
    <inertia ixx="5e-05" iyy="3.2e-05" izz="3.2e-05" ixy="-0.0" iyz="-0.0" ixz="-0.0"/>
  </inertial>
  <visual>
    <origin xyz="0.103583 0.006625 -0.024" rpy="0 0 0"/>
    <geometry>
      <mesh filename="package://urdf_description/meshes/wheel_link_1.stl" scale="0.001 0.001 0.001"/>
    </geometry>
    <material name="silver"/>
  </visual>
  <collision>
    <origin xyz="0.103583 0.006625 -0.024" rpy="0 0 0"/>
    <geometry>
      <mesh filename="package://urdf_description/meshes/wheel_link_1.stl" scale="0.001 0.001 0.001"/>
    </geometry>
  </collision>
</link>

<link name="wheel_link_2">
  <inertial>
    <origin xyz="-0.0039033081055799 0.006580816821685306 3.642650617940307e-05" rpy="0 0 0"/>
    <mass value="0.17051038938064"/>
    <inertia ixx="3.7e-05" iyy="4.6e-05" izz="3.2e-05" ixy="-8e-06" iyz="0.0" ixz="-0.0"/>
  </inertial>
  <visual>
    <origin xyz="-0.068227 0.105819 -0.024" rpy="0 0 0"/>
    <geometry>
      <mesh filename="package://urdf_description/meshes/wheel_link_2.stl" scale="0.001 0.001 0.001"/>
    </geometry>
    <material name="silver"/>
  </visual>
  <collision>
    <origin xyz="-0.068227 0.105819 -0.024" rpy="0 0 0"/>
    <geometry>
      <mesh filename="package://urdf_description/meshes/wheel_link_2.stl" scale="0.001 0.001 0.001"/>
    </geometry>
  </collision>
</link>

<link name="wheel_link_3">
  <inertial>
    <origin xyz="-0.0037745189185399014 -0.006655427439052869 7.703379049328954e-05" rpy="0 0 0"/>
    <mass value="0.17051038938064"/>
    <inertia ixx="3.7e-05" iyy="4.6e-05" izz="3.2e-05" ixy="8e-06" iyz="-0.0" ixz="-0.0"/>
  </inertial>
  <visual>
    <origin xyz="-0.068227 -0.09257 -0.024" rpy="0 0 0"/>
    <geometry>
      <mesh filename="package://urdf_description/meshes/wheel_link_3.stl" scale="0.001 0.001 0.001"/>
    </geometry>
    <material name="silver"/>
  </visual>
  <collision>
    <origin xyz="-0.068227 -0.09257 -0.024" rpy="0 0 0"/>
    <geometry>
      <mesh filename="package://urdf_description/meshes/wheel_link_3.stl" scale="0.001 0.001 0.001"/>
    </geometry>
  </collision>
</link>

<link name="lidar_link">
  <inertial>
    <origin xyz="-0.029581681955466045 0.042548549097526214 0.028542673476791153" rpy="0 0 0"/>
    <mass value="0.8868464662474358"/>
    <inertia ixx="0.001061" iyy="0.000673" izz="0.001038" ixy="4e-06" iyz="0.00019" ixz="-1.1e-05"/>
  </inertial>
  <visual>
    <origin xyz="-0.029369 0.014322 -0.048" rpy="0 0 0"/>
    <geometry>
      <mesh filename="package://urdf_description/meshes/lidar_link_1.stl" scale="0.001 0.001 0.001"/>
    </geometry>
    <material name="black"/>
  </visual>
  <collision>
    <origin xyz="-0.029369 0.014322 -0.048" rpy="0 0 0"/>
    <geometry>
      <mesh filename="package://urdf_description/meshes/lidar_link_1.stl" scale="0.001 0.001 0.001"/>
    </geometry>
  </collision>
</link>

<link name="laser">
    <inertial>
      <origin xyz="0 0 0" rpy="0 0 3.14"/>
      <mass value="0.125"/>
      <inertia ixx="0.000"  ixy="0"  ixz="0" iyy="0.000" iyz="0" izz="0.001" />
    </inertial>
</link>


<!--base-footprint joint-->

<joint name="dummy_joint" type="fixed">
  <parent link="base_footprint"/>
  <child link="base_link"/>
  <origin xyz="0 0 0" rpy="0 0 0"/>
</joint>

<!--base-lidar joint-->

<joint name="lidar_joint" type="fixed">
  <parent link="base_link"/>
  <child link="laser"/>
  <!--origin xyz="0 -0.03 0.15" rpy="0 0 1.57"/-->
  <origin xyz="0.03 0 0.156" rpy="0 0 0"/>
</joint>


<joint name="Rigid1" type="fixed">
  <origin xyz="0.029369 -0.014322 0.048" rpy="0 0 0 "/>
  <parent link="base_link"/>
  <child link="lidar_link"/>
</joint>

<joint name="Rev3" type="continuous">
  <origin xyz="-0.103583 -0.006625 0.024" rpy="0 0 0"/>
  <parent link="base_link"/>
  <child link="wheel_link_1"/>
  <axis xyz="-1.0 -0.0 -0.0"/>
</joint>

<joint name="Rev4" type="continuous">
  <origin xyz="0.068227 -0.105819 0.024" rpy="0 0 0"/>
  <parent link="base_link"/>
  <child link="wheel_link_2"/>
  <axis xyz="0.5 -0.866025 -0.0"/>
</joint>

<joint name="Rev5" type="continuous">
  <origin xyz="0.068227 0.09257 0.024" rpy="0 0 0"/>
  <parent link="base_link"/>
  <child link="wheel_link_3"/>
  <axis xyz="0.5 0.866025 -0.0"/>
</joint>

<xacro:property name="body_color" value="Gazebo/Black" />
<xacro:property name="body_color1" value="Gazebo/Silver" />
<xacro:property name="body_color2" value="Gazebo/Yellow" />
<gazebo reference="base_link">
  <material>${body_color1}</material>
  <mu1>0.2</mu1>
  <mu2>0.2</mu2>
  <selfCollide>true</selfCollide>
  <gravity>true</gravity>
</gazebo>

 <gazebo reference="laser">
    <material>${body_color2}</material>
    <sensor type="ray" name="lds_lfcd_sensor">
      <pose>0 0 0 0 0 0</pose>
      <visualize>true</visualize>
      <update_rate>30</update_rate>
      <ray>
        <scan>
          <horizontal>
            <samples>360</samples>
            <resolution>1</resolution>
              <min_angle>-3.12413</min_angle>
              <max_angle>3.14159</max_angle>
          </horizontal>
        </scan>
        <range>
          <min>0.120</min>
          <max>10</max>
          <resolution>0.01</resolution>
        </range>
        <noise>
          <type>gaussian</type>
          <mean>0.0</mean>
          <stddev>0.01</stddev>
        </noise>
      </ray>
      <plugin name="gazebo_ros_lds_lfcd_controller" filename="libgazebo_ros_laser.so">
        <topicName>scan</topicName>
        <frameName>laser</frameName>
      </plugin>
    </sensor>
 </gazebo>
  
<!--gazebo reference="laser">
  <material>${body_color2}</material>
        <sensor name="laser" type="ray">
            <pose> 0 0 0 0 0 0 </pose>
            <visualize>true</visualize>
            <update_rate>40</update_rate>
            <ray>
                <scan>
                    <horizontal>
                        <samples>720</samples>
                        <resolution>1</resolution>
                        <min_angle>-3.12413</min_angle>
                        <max_angle>3.14159</max_angle>
                    </horizontal>
                </scan>
                <range>
                    <min>0.15</min>
                    <max>12</max>
                    <resolution>0.01</resolution>
                </range>
            </ray>
            <plugin name="laser_back" filename="libgazebo_ros_laser.so">
                <output_type>sensor_msgs/LaserScan</output_type>
                <frame_name>laser</frame_name>
                <topicName>scan</topicName>
            </plugin>
        </sensor>
  <mu1>0.2</mu1>
  <mu2>0.2</mu2>
  <selfCollide>true</selfCollide>
  <gravity>true</gravity>
</gazebo!-->

<gazebo reference="wheel_link_1">
  <material>${body_color1}</material>
  <mu1>0.2</mu1>
  <mu2>0.2</mu2>
  <selfCollide>true</selfCollide>
</gazebo>

<gazebo reference="wheel_link_2">
  <material>${body_color1}</material>
  <mu1>0.2</mu1>
  <mu2>0.2</mu2>
  <selfCollide>true</selfCollide>
</gazebo>

<gazebo reference="wheel_link_3">
  <material>${body_color1}</material>
  <mu1>0.2</mu1>
  <mu2>0.2</mu2>
  <selfCollide>true</selfCollide>
</gazebo>

<gazebo>
    <plugin name="object_controller" filename="libgazebo_ros_planar_move.so">
      <commandTopic>cmd_vel</commandTopic>
      <odometryTopic>odom</odometryTopic>
      <odometryFrame>odom</odometryFrame>
      <odometryRate>30</odometryRate>
      <robotBaseFrame>base_footprint</robotBaseFrame>
    </plugin>
</gazebo>


</robot>
