<?xml version="1.0" ?>
<robot name="arobota2" xmlns:xacro="http://www.ros.org/wiki/xacro">

<xacro:include filename="$(find arobota2_description)/urdf/materials.xacro" />
<xacro:include filename="$(find arobota2_description)/urdf/arobota2.trans" />
<xacro:include filename="$(find arobota2_description)/urdf/arobota2.gazebo" />

<link name="base_footprint"/>

<joint name="base_joint" type="fixed">
  <origin xyz="0 0 0.02" rpy="0 0 1.57" />
  <parent link="base_footprint"/>
  <child link="base_link" />
</joint>

<link name="base_link">
  <inertial>
    <origin xyz="0.025849766118147825 0.0 0.03881966145827727" rpy="0 0 0"/>
    <!-- <origin xyz="0.025849766118147825 -0.2746887727345287 0.03881966145827727" rpy="0 0 0"/> -->
    <mass value="3.209815868392884"/>
    <inertia ixx="0.006859" iyy="0.008899" izz="0.009206" ixy="0.000105" iyz="-0.000357" ixz="0.000142"/>
  </inertial>
  <visual>
    <origin xyz="-0.02641 0.275004 0" rpy="0 0 0"/>
    <geometry>
      <mesh filename="package://arobota2_description/meshes/base_link.stl" scale="0.001 0.001 0.001"/>
    </geometry>
    <material name="silver"/>
  </visual>
  <collision>
    <origin xyz="-0.02641 0.275004 0" rpy="0 0 0"/>
    <geometry>
      <mesh filename="package://arobota2_description/meshes/base_link.stl" scale="0.001 0.001 0.001"/>
    </geometry>
  </collision>
</link>

<link name="wheel_right_1">
  <inertial>
    <origin xyz="-0.02014975433258679 -2.6938424269040695e-08 -3.341489744589088e-07" rpy="0 0 0"/>
    <mass value="0.49277229166154995"/>
    <inertia ixx="0.000313" iyy="0.000172" izz="0.000172" ixy="0.0" iyz="-0.0" ixz="-0.0"/>
  </inertial>
  <visual>
    <origin xyz="0.04609 0.275004 -0.025996" rpy="0 0 0"/>
    <geometry>
      <mesh filename="package://arobota2_description/meshes/wheel_right_1.stl" scale="0.001 0.001 0.001"/>
    </geometry>
    <material name="silver"/>
  </visual>
  <collision>
    <origin xyz="0.04609 0.275004 -0.025996" rpy="0 0 0"/>
    <geometry>
      <mesh filename="package://arobota2_description/meshes/wheel_right_1.stl" scale="0.001 0.001 0.001"/>
    </geometry>
  </collision>
</link>

<link name="wheel_left_1">
  <inertial>
    <origin xyz="0.020149235532235063 0.0 -3.95768489168391e-07" rpy="0 0 0"/>
    <mass value="0.49277229166154995"/>
    <inertia ixx="0.000313" iyy="0.000172" izz="0.000172" ixy="0.0" iyz="-0.0" ixz="0.0"/>
  </inertial>
  <visual>
    <origin xyz="-0.09891 0.275 -0.02675" rpy="0 0 0"/>
    <geometry>
      <mesh filename="package://arobota2_description/meshes/wheel_left_1.stl" scale="0.001 0.001 0.001"/>
    </geometry>
    <material name="silver"/>
  </visual>
  <collision>
    <origin xyz="-0.09891 0.275 -0.02675" rpy="0 0 0"/>
    <geometry>
      <mesh filename="package://arobota2_description/meshes/wheel_left_1.stl" scale="0.001 0.001 0.001"/>
    </geometry>
  </collision>
</link>

<link name="laser">
    <inertial>
      <origin xyz="0 0 0" rpy="0 0 0"/>
      <mass value="0.125"/>
      <inertia ixx="0.000"  ixy="0"  ixz="0" iyy="0.000" iyz="0" izz="0.001" />
    </inertial>
</link>

<joint name="lidar_joint" type="fixed">
  <parent link="base_link"/>
  <child link="laser"/>
  <origin xyz="0 -0.03 0.15" rpy="0 0 1.57"/>
</joint>

<joint name="Rev13" type="continuous">
  <origin xyz="-0.0725 0.0 0.025996" rpy="0 0 0"/>
  <!-- <origin xyz="-0.04609 -0.275004 0.025996" rpy="0 0 0"/> -->
  <parent link="base_link"/>
  <child link="wheel_right_1"/>
  <axis xyz="-1.0 0.0 0.0"/>
</joint>

<joint name="Rev14" type="continuous">
  <origin xyz="0.0725 0.0 0.02675" rpy="0 0 0"/>
  <!-- <origin xyz="0.09891 -0.275 0.02675" rpy="0 0 0"/> -->
  <parent link="base_link"/>
  <child link="wheel_left_1"/>
  <axis xyz="1.0 0.0 -0.0"/>
</joint>

</robot>
